Workbook

Sheet Summary
A1: Agrobo robot BOM summary (USD)
A3: Item | B3: Pilot qty (1-5) | C3: At 100 units
A4: AB-1 base platform | B4: ='AB-1_base'!H45 | C4: ='AB-1_base'!K45
A5: HM-1 harvester implement | B5: ='HM-1_harvester_implement'!H15 | C5: ='HM-1_harvester_implement'!K15
A6: EE-1 end-effector (x2) | B6: =2*'EE-1_end_effector'!H17 | C6: =2*'EE-1_end_effector'!K17
A7: Harvester robot total | B7: =SUM(B4:B6) | C7: =SUM(C4:C6)
A9: Other modules (pilot, design estimate)
A10: LW-1 laser weeder implement (2 heads) | B10: 30700
A11: LW-1M mechanical aisle cultivator (alternative) | B11: 4000
A12: SP-1 spot sprayer implement (replaces micro-doser) | B12: 5400
A13: HL-1 hauler (AB-1 base + tote rack, no arms) | B13: 29687
A14: SU-1 scout UAV (ArduPilot quad, multispectral) | B14: 11000
A15: DK-1 dock/charger (serves ~2 UGVs) | B15: 7600
A17: Prices checked 2026-10-21. 'quote' = public list price (URL in notes); 'est' = engineering estimate, get quotes before ordering.

Sheet AB-1_base
A1: part_no | B1: subsystem | C1: description | D1: manufacturer | E1: model_mpn | F1: qty | G1: unit_usd | H1: ext_usd | I1: price_basis | J1: vol100_factor | K1: ext_usd_at_100_units | L1: notes
A2: AB1-101 | B2: Frame | C2: T-slot profile 1.5 in square, cut to length (see cut list) | D2: 80/20 Inc. | E2: 1515 (or 1515-LITE for cross members) | F2: 1 | G2: 980 | H2: =F2*G2 | I2: est | J2: 0.6 | K2: =ROUND(H2*J2,0) | L2: ~21 m total incl. mast; welded 6061 frame at volume
A3: AB1-102 | B3: Frame | C3: Fastener kit: T-nuts, anchors, 90 deg gussets, M8 SS hardware | D3: 80/20 Inc. / McMaster-Carr | E3: assorted | F3: 1 | G3: 650 | H3: =F3*G3 | I3: est | J3: 0.5 | K3: =ROUND(H3*J3,0) | L3: stainless or zinc-nickel, coastal FL
A4: AB1-201 | B4: Frame | C4: Deck plate 3 mm 5052-H32, laser cut | D4: SendCutSend | E4: cad/dxf/AB1-201 | F4: 1 | G4: 260 | H4: =F4*G4 | I4: est | J4: 0.5 | K4: =ROUND(H4*J4,0) | L4: DXF provided
A5: AB1-202 | B5: Frame | C5: Axle plate 10 mm 6061-T6, laser cut + shaft clamp slot | D5: SendCutSend | E5: cad/dxf/AB1-202 | F5: 4 | G5: 55 | H5: =F5*G5 | I5: est | J5: 0.5 | K5: =ROUND(H5*J5,0) | L5: DXF provided
A6: AB1-203 | B6: Frame | C6: Leg gusset plate 10 mm 6061-T6 | D6: SendCutSend | E6: cad/step (from frame) | F6: 4 | G6: 35 | H6: =F6*G6 | I6: est | J6: 0.5 | K6: =ROUND(H6*J6,0)
A7: AB1-204 | B7: Frame | C7: Shaft clamp block, 6061 CNC, 30 mm bore | D7: Xometry | E7: cad/step | F7: 4 | G7: 70 | H7: =F7*G7 | I7: est | J7: 0.4 | K7: =ROUND(H7*J7,0) | L7: confirm hub motor shaft dia + flats
A8: AB1-205 | B8: Frame | C8: Powder coat / hard anodise frame parts | D8: local | F8: 1 | G8: 400 | H8: =F8*G8 | I8: est | J8: 0.6 | K8: =ROUND(H8*J8,0) | L8: salt air + fertiliser exposure
A9: AB1-301 | B9: Drive | C9: Brushless hub motor 3 kW, 48 V, 130 N m nom / 200 N m peak, IP65 | D9: OZO Electric | E9: ref 000500 | F9: 4 | G9: 465 | H9: =F9*G9 | I9: quote | J9: 0.8 | K9: =ROUND(H9*J9,0) | L9: EUR 399 incl. tax https://ozo-electric.com/en/agricultural-construction-wheel-motors/558692-brushless-electric-hub-motor-3000w-130nm-45kmh-48v-to-72v.html
A10: AB1-302 | B10: Drive | C10: Turf tyre 20x8.00-10 on 10 in steel rim, 4x100 | D10: Carlisle / Kenda | E10: Turf Saver 20x8.00-10 | F10: 4 | G10: 95 | H10: =F10*G10 | I10: est | J10: 0.8 | K10: =ROUND(H10*J10,0) | L10: flotation on sand
A11: AB1-303 | B11: Drive | C11: FOC motor controller 75 V 100 A, CAN, hall + sensorless | D11: Flipsky | E11: FSESC 75100 (VESC 6 fw) | F11: 4 | G11: 165 | H11: =F11*G11 | I11: est | J11: 0.7 | K11: =ROUND(H11*J11,0) | L11: potted in AB1-403 box; ros2 vesc driver
A12: AB1-401 | B12: Power | C12: LFP prismatic cell 3.2 V 105 Ah (16S2P = 51.2 V 210 Ah, 10.75 kWh) | D12: EVE Energy | E12: LF105 | F12: 32 | G12: 52 | H12: =F12*G12 | I12: est | J12: 0.7 | K12: =ROUND(H12*J12,0) | L12: grade A, matched; UN38.3 for shipping
A13: AB1-402 | B13: Power | C13: BMS 16S with CAN, contactor + precharge control | D13: Orion / Ewert Energy | E13: Orion BMS 2 (24-cell) | F13: 1 | G13: 950 | H13: =F13*G13 | I13: est | J13: 0.6 | K13: =ROUND(H13*J13,0)
A14: AB1-403 | B14: Power | C14: Keel pack enclosure 5052 sheet, IP67 gasket, cell compression plates | D14: local sheet-metal | E14: cad/step keel | F14: 1 | G14: 650 | H14: =F14*G14 | I14: est | J14: 0.5 | K14: =ROUND(H14*J14,0)
A15: AB1-404 | B15: Power | C15: Busbars, cell fuses, thermistors, sense harness | D15: assorted | F15: 1 | G15: 250 | H15: =F15*G15 | I15: est | J15: 0.6 | K15: =ROUND(H15*J15,0)
A16: AB1-405 | B16: Power | C16: Main contactor 500 A, 12 V coil, sealed | D16: TE Kilovac | E16: EV200AAANA | F16: 1 | G16: 165 | H16: =F16*G16 | I16: est | J16: 0.8 | K16: =ROUND(H16*J16,0)
A17: AB1-406 | B17: Power | C17: Precharge relay + 50 ohm 50 W resistor | D17: assorted | F17: 1 | G17: 60 | H17: =F17*G17 | I17: est | J17: 0.8 | K17: =ROUND(H17*J17,0)
A18: AB1-407 | B18: Power | C18: Main fuse 200 A Class T + holder | D18: Littelfuse / Blue Sea | E18: JLLN200 + 5502 | F18: 1 | G18: 95 | H18: =F18*G18 | I18: est | J18: 0.8 | K18: =ROUND(H18*J18,0)
A19: AB1-408 | B19: Power | C19: Manual battery disconnect (lockout) | D19: Blue Sea | E19: 9003e | F19: 1 | G19: 70 | H19: =F19*G19 | I19: est | J19: 0.8 | K19: =ROUND(H19*J19,0) | L19: LOTO point for service
A20: AB1-409 | B20: Power | C20: Battery connector 8 mm, 200 A, IP67, keyed pair | D20: Amphenol | E20: SurLok Plus | F20: 1 | G20: 90 | H20: =F20*G20 | I20: est | J20: 0.8 | K20: =ROUND(H20*J20,0)
A21: AB1-410 | B21: Power | C21: DC-DC 48->24 V 480 W DIN rail | D21: MEAN WELL | E21: DDR-480C-24 | F21: 1 | G21: 120 | H21: =F21*G21 | I21: est | J21: 0.8 | K21: =ROUND(H21*J21,0) | L21: 33.6-67.2 V input
A22: AB1-411 | B22: Power | C22: DC-DC 48->12 V 240 W DIN rail | D22: MEAN WELL | E22: DDR-240C-12 | F22: 1 | G22: 80 | H22: =F22*G22 | I22: est | J22: 0.8 | K22: =ROUND(H22*J22,0) | L22: Jetson + router
A23: AB1-412 | B23: Power | C23: Fused distribution: DIN fuse blocks, breakers, terminals | D23: Phoenix Contact | E23: assorted | F23: 1 | G23: 260 | H23: =F23*G23 | I23: est | J23: 0.7 | K23: =ROUND(H23*J23,0)
A24: AB1-413 | B24: Power | C24: Charge inlet: spring dock contacts 2x 150 A + pilot pin | D24: Staubli / REMA | E24: MC / DIN 160A | F24: 1 | G24: 380 | H24: =F24*G24 | I24: est | J24: 0.6 | K24: =ROUND(H24*J24,0) | L24: dock side in DK-1
A25: AB1-501 | B25: Safety | C25: Safety relay, dual-channel E-stop + reset, PL d | D25: Pilz | E25: PNOZ s4 24VDC (750104) | F25: 1 | G25: 310 | H25: =F25*G25 | I25: est | J25: 0.9 | K25: =ROUND(H25*J25,0)
A26: AB1-502 | B26: Safety | C26: E-stop mushroom, IP69K, 2NC, yellow housing | D26: IDEC / Schneider | E26: XW1E / XB4 | F26: 4 | G26: 45 | H26: =F26*G26 | I26: est | J26: 0.8 | K26: =ROUND(H26*J26,0) | L26: 4 corners
A27: AB1-503 | B27: Safety | C27: Wireless E-stop transmitter + receiver, 1 km | D27: Humanistic Robotics | E27: HRI Wireless Emergency Stop | F27: 1 | G27: 1950 | H27: =F27*G27 | I27: est | J27: 0.8 | K27: =ROUND(H27*J27,0) | L27: one handheld per field tech
A28: AB1-504 | B28: Safety | C28: Pressure-sensitive safety edge bumper + controller | D28: Mayser / ASO | E28: SENTIR edge + SG-EFS | F28: 2 | G28: 480 | H28: =F28*G28 | I28: est | J28: 0.8 | K28: =ROUND(H28*J28,0) | L28: front + rear
A29: AB1-505 | B29: Safety | C29: Safety contactors (drive bus + arm bus cut) | D29: Schneider | E29: TeSys D LC1D25BD | F29: 2 | G29: 120 | H29: =F29*G29 | I29: est | J29: 0.9 | K29: =ROUND(H29*J29,0)
A30: AB1-506 | B30: Safety | C30: Stack light / beacon IP67, RGB + buzzer | D30: Banner | E30: TL50 Pro | F30: 1 | G30: 180 | H30: =F30*G30 | I30: est | J30: 0.8 | K30: =ROUND(H30*J30,0)
A31: AB1-601 | B31: Compute | C31: Edge computer 275 TOPS, 64 GB | D31: NVIDIA | E31: Jetson AGX Orin 64GB Developer Kit | F31: 1 | G31: 3499 | H31: =F31*G31 | I31: quote | J31: 0.85 | K31: =ROUND(H31*J31,0) | L31: post-July-2026 price https://www.cnx-software.com/2026/07/22/nvidia-increases-the-price-of-jetson-modules-and-devkits-by-up-to-101/; rugged carrier at volume
A32: AB1-602 | B32: Compute | C32: NVMe SSD 2 TB industrial (logging, Field Ledger cache) | D32: Innodisk / Samsung | E32: PM9A3-class | F32: 1 | G32: 220 | H32: =F32*G32 | I32: est | J32: 0.8 | K32: =ROUND(H32*J32,0)
A33: AB1-603 | B33: Compute | C33: Real-time I/O MCU + 3x CAN-FD (micro-ROS) | D33: PJRC + SK Pang | E33: Teensy 4.1 + triple CAN board | F33: 1 | G33: 95 | H33: =F33*G33 | I33: est | J33: 0.6 | K33: =ROUND(H33*J33,0) | L33: motors, BMS, safety status
A34: AB1-606 | B34: Comms | C34: Industrial unmanaged Ethernet switch 8x GbE, 12-48 VDC | D34: Moxa | E34: EDS-208A-T | F34: 1 | G34: 220 | H34: =F34*G34 | I34: est | J34: 0.8 | K34: =ROUND(H34*J34,0) | L34: lidar, 2 arms, router, Teensy
A35: AB1-607 | B35: Compute | C35: Powered industrial USB3 hub, 4 port, locking | D35: StarTech / Advantech | E35: ST4300USB3GB-class | F35: 1 | G35: 160 | H35: =F35*G35 | I35: est | J35: 0.8 | K35: =ROUND(H35*J35,0) | L35: 2x D405, GNSS, IMU
A36: AB1-604 | B36: Comms | C36: 5G/LTE industrial router, dual SIM, Wi-Fi 6 | D36: Teltonika | E36: RUTX50 | F36: 1 | G36: 520 | H36: =F36*G36 | I36: est | J36: 0.8 | K36: =ROUND(H36*J36,0)
A37: AB1-605 | B37: Comms | C37: Roof antennas 5G MIMO + Wi-Fi, IP67 | D37: Taoglas / Poynting | E37: MA1508 / OMNI-402 | F37: 1 | G37: 160 | H37: =F37*G37 | I37: est | J37: 0.8 | K37: =ROUND(H37*J37,0)
A38: AB1-701 | B38: Sensing | C38: 3D lidar 360x59 deg, 70 m, IP67 | D38: Livox | E38: Mid-360 | F38: 1 | G38: 749 | H38: =F38*G38 | I38: quote | J38: 0.8 | K38: =ROUND(H38*J38,0) | L38: https://www.livoxtech.com/news/mid360_launch
A39: AB1-702 | B39: Sensing | C39: Dual-antenna RTK GNSS heading kit (2x ZED-F9P + 2 antennas) | D39: ArduSimple | E39: simpleRTK2B Heading kit | F39: 1 | G39: 650 | H39: =F39*G39 | I39: est | J39: 0.8 | K39: =ROUND(H39*J39,0) | L39: FDOT FPRN NTRIP corrections (free in FL)
A40: AB1-703 | B40: Sensing | C40: Tactical-grade AHRS IMU | D40: HBK MicroStrain | E40: 3DM-CV7-AHRS | F40: 1 | G40: 1000 | H40: =F40*G40 | I40: est | J40: 0.8 | K40: =ROUND(H40*J40,0)
...

Sheet HM-1_harvester_implement
A1: part_no | B1: subsystem | C1: description | D1: manufacturer | E1: model_mpn | F1: qty | G1: unit_usd | H1: ext_usd | I1: price_basis | J1: vol100_factor | K1: ext_usd_at_100_units | L1: notes
A2: HM1-001 | B2: Arms | C2: 6-axis cobot 5 kg / 922 mm, IP54 arm, DC MINI controller 30-60 VDC | D2: FAIRINO | E2: FR5 (DC controller) | F2: 2 | G2: 6999 | H2: =F2*G2 | I2: quote | J2: 0.85 | K2: =ROUND(H2*J2,0) | L2: https://top3dshop.com/product/fairino-fr5-robotic-arm; confirm DC controller price + IP65 option
A3: HM1-002 | B3: Arms | C3: Arm dress pack + cable carrier (vacuum, RS485, 24 V, USB3) | D3: igus | E3: triflex R TRE.40 | F3: 2 | G3: 250 | H3: =F3*G3 | I3: est | J3: 0.7 | K3: =ROUND(H3*J3,0)
A4: HM1-003 | B4: Arms | C4: Arm rain/dust cover, breathable PTFE fabric | D4: RoboSuits / Roboworld | E4: custom FR5 | F4: 2 | G4: 450 | H4: =F4*G4 | I4: est | J4: 0.6 | K4: =ROUND(H4*J4,0) | L4: keeps the IP54 arm usable in FL rain
A5: HM1-101 | B5: Mast | C5: Arm mount plate 20 mm 6061, machined | D5: Xometry | E5: cad/dxf/HM1-101 | F5: 2 | G5: 140 | H5: =F5*G5 | I5: est | J5: 0.5 | K5: =ROUND(H5*J5,0) | L5: verify FR5 base bolt pattern from vendor drawing
A6: HM1-102 | B6: Mast | C6: 1530 profile posts + beams (in AB1-101 cut list) + gussets | D6: 80/20 Inc. | E6: 1530 | F6: 1 | G6: 520 | H6: =F6*G6 | I6: est | J6: 0.6 | K6: =ROUND(H6*J6,0)
A7: HM1-201 | B7: Perception | C7: Stereo camera, global shutter, GMSL2, IP67, wide lens | D7: Stereolabs | E7: ZED X (ZED-311110) | F7: 2 | G7: 599 | H7: =F7*G7 | I7: quote | J7: 0.85 | K7: =ROUND(H7*J7,0) | L7: https://stereolabs.com/store/products/zed-x-stereo-camera
A8: HM1-202 | B8: Perception | C8: GMSL2 capture card, 2 ports, for AGX Orin | D8: Stereolabs | E8: ZED Link Duo | F8: 1 | G8: 379 | H8: =F8*G8 | I8: quote | J8: 0.85 | K8: =ROUND(H8*J8,0) | L8: https://stereolabs.com/store/products/zed-x-stereo-camera
A9: HM1-203 | B9: Perception | C9: GMSL2 Fakra cable 5 m | D9: Stereolabs | F9: 2 | G9: 45 | H9: =F9*G9 | I9: quote | J9: 0.8 | K9: =ROUND(H9*J9,0)
A10: HM1-301 | B10: Vacuum | C10: Diaphragm vacuum pump 24 V, -75 kPa, 10 L/min | D10: Parker / Thomas | E10: BTC-IIS / 2002 series | F10: 2 | G10: 220 | H10: =F10*G10 | I10: est | J10: 0.7 | K10: =ROUND(H10*J10,0) | L10: one per arm
A11: HM1-302 | B11: Vacuum | C11: 3/2 solenoid valve 24 V + blow-off | D11: SMC | E11: VQ110 / SYJ3000 | F11: 2 | G11: 60 | H11: =F11*G11 | I11: est | J11: 0.8 | K11: =ROUND(H11*J11,0)
A12: HM1-303 | B12: Vacuum | C12: Digital vacuum switch (seal / contact detect) | D12: SMC | E12: ZSE20A | F12: 2 | G12: 110 | H12: =F12*G12 | I12: est | J12: 0.8 | K12: =ROUND(H12*J12,0)
A13: HM1-401 | B13: Logistics | C13: Stacking tote 600x500x350, food-grade, foam liner | D13: ORBIS | E13: Stak-N-Nest equiv. | F13: 2 | G13: 75 | H13: =F13*G13 | I13: est | J13: 0.8 | K13: =ROUND(H13*J13,0) | L13: 35 kg fruit each
A14: HM1-402 | B14: Logistics | C14: Tote transfer deck: 24 V MDR roller zone + driver card | D14: Interroll | E14: EC5000 + DriveControl 20 | F14: 2 | G14: 1200 | H14: =F14*G14 | I14: est | J14: 0.6 | K14: =ROUND(H14*J14,0) | L14: rolls totes sideways to the hauler at the headland
G15: TOTAL | H15: =SUM(H2:H14) | K15: =SUM(K2:K14)

Sheet EE-1_end_effector
A1: part_no | B1: subsystem | C1: description | D1: manufacturer | E1: model_mpn | F1: qty | G1: unit_usd | H1: ext_usd | I1: price_basis | J1: vol100_factor | K1: ext_usd_at_100_units | L1: notes
A2: EE1-001 | B2: Mechanical | C2: ISO 9409-1-50-4-M6 flange adapter, 6061 CNC | D2: Xometry | E2: cad/step/EE1-001 | F2: 1 | G2: 85 | H2: =F2*G2 | I2: est | J2: 0.4 | K2: =ROUND(H2*J2,0)
A3: EE1-002 | B3: Mechanical | C3: Sealed housing, MJF PA12 + O-ring grooves (IP65 target) | D3: Xometry / HP MJF | E3: cad/stl/EE1-002 | F3: 1 | G3: 120 | H3: =F3*G3 | I3: est | J3: 0.3 | K3: =ROUND(H3*J3,0) | L3: injection mould at volume
A4: EE1-003 | B4: Mechanical | C4: Front plate with 3 finger clevises, MJF PA12 | D4: Xometry | E4: cad/stl/EE1-003 | F4: 1 | G4: 45 | H4: =F4*G4 | I4: est | J4: 0.3 | K4: =ROUND(H4*J4,0)
A5: EE1-004 | B5: Mechanical | C5: Fin-Ray finger TPU 95A (3 fitted + 3 spare) | D5: in-house FDM / Shore 95A | E5: cad/stl/EE1-004 | F5: 6 | G5: 8 | H5: =F5*G5 | I5: est | J5: 0.5 | K5: =ROUND(H5*J5,0) | L5: food-contact TPU; consumable, swap weekly
A6: EE1-005 | B6: Mechanical | C6: D405 bracket, 6061 | D6: Xometry | E6: cad/step/EE1-005 | F6: 1 | G6: 45 | H6: =F6*G6 | I6: est | J6: 0.4 | K6: =ROUND(H6*J6,0)
A7: EE1-006 | B7: Mechanical | C7: Lead-screw cam ring, bearings, lip seal, O-rings, pins | D7: McMaster-Carr | E7: assorted | F7: 1 | G7: 60 | H7: =F7*G7 | I7: est | J7: 0.6 | K7: =ROUND(H7*J7,0)
A8: EE1-101 | B8: Actuation | C8: Smart servo, current-based force control, RS485 | D8: ROBOTIS | E8: DYNAMIXEL XM430-W350-R | F8: 1 | G8: 290 | H8: =F8*G8 | I8: est | J8: 0.8 | K8: =ROUND(H8*J8,0) | L8: grip force via current limit
A9: EE1-102 | B9: Actuation | C9: Bellows suction cup 40 mm, 1.5 folds, food-grade silicone | D9: Piab | E9: BX40P-class | F9: 1 | G9: 35 | H9: =F9*G9 | I9: est | J9: 0.8 | K9: =ROUND(H9*J9,0)
A10: EE1-103 | B10: Actuation | C10: Micro linear actuator 100 mm (used 65 mm), position feedback, 12 V | D10: Actuonix | E10: L16-100-63-12-P | F10: 1 | G10: 90 | H10: =F10*G10 | I10: est | J10: 0.7 | K10: =ROUND(H10*J10,0) | L10: retracts the suction cup 65 mm to seat the fruit
A11: EE1-104 | B11: Actuation | C11: Cup rod guide: linear bushing + PTFE wiper seal | D11: Misumi / igus | E11: assorted | F11: 1 | G11: 30 | H11: =F11*G11 | I11: est | J11: 0.7 | K11: =ROUND(H11*J11,0)
A12: EE1-201 | B12: Sensing | C12: Short-range stereo depth camera (7-50 cm), global shutter | D12: RealSense | E12: D405 | F12: 1 | G12: 272 | H12: =F12*G12 | I12: est | J12: 0.85 | K12: =ROUND(H12*J12,0) | L12: + rugged 3 m USB-C
A13: EE1-202 | B13: Sensing | C13: ToF proximity sensor in palm (fruit contact distance) | D13: ST | E13: VL53L4CD | F13: 1 | G13: 15 | H13: =F13*G13 | I13: est | J13: 0.8 | K13: =ROUND(H13*J13,0)
A14: EE1-203 | B14: Lighting | C14: LED ring light 24 V, diffused, IP65 | D14: Advanced Illumination / generic | F14: 1 | G14: 60 | H14: =F14*G14 | I14: est | J14: 0.6 | K14: =ROUND(H14*J14,0) | L14: constant lighting day + night
A15: EE1-301 | B15: Electrical | C15: M12 8-pin tool connector, RS485 interface, wiring | D15: Lumberg / ROBOTIS | E15: U2D2-class | F15: 1 | G15: 90 | H15: =F15*G15 | I15: est | J15: 0.6 | K15: =ROUND(H15*J15,0)
A16: EE1-302 | B16: Electrical | C16: Active USB3 cable 3 m, rugged | D16: Newnex / generic | F16: 1 | G16: 45 | H16: =F16*G16 | I16: est | J16: 0.8 | K16: =ROUND(H16*J16,0)
G17: TOTAL | H17: =SUM(H2:H16) | K17: =SUM(K2:K16)

Sheet other_modules_estimate
A1: module | B1: line | C1: qty | D1: unit_usd | E1: ext_usd
A2: LW-1 laser weeder implement (2 heads) | B2: Sealed RF CO2 laser 100 W, air-cooled | C2: 2 | D2: 9000 | E2: 18000
A3: LW-1 laser weeder implement (2 heads) | B3: 10.6 um galvo scan head + F-theta | C3: 2 | D3: 3500 | E3: 7000
A4: LW-1 laser weeder implement (2 heads) | B4: Light-tight hood with brush skirt + interlocks (Class 4) | C4: 1 | D4: 1500 | E4: 1500
A5: LW-1 laser weeder implement (2 heads) | B5: Global-shutter RGB cameras + strobe | C5: 2 | D5: 800 | E5: 1600
A6: LW-1 laser weeder implement (2 heads) | B6: Cooling, frame, auto-coupler, harness | C6: 1 | D6: 2600 | E6: 2600
A7: LW-1M mechanical aisle cultivator (alternative) | B7: Electric rotary hoe 0.7 m (aisle between plastic beds), 48 V 1.5 kW | C7: 1 | D7: 2600 | E7: 2600
A8: LW-1M mechanical aisle cultivator (alternative) | B8: Depth wheels, guard, coupler, harness | C8: 1 | D8: 1400 | E8: 1400
A9: SP-1 spot sprayer implement (replaces micro-doser) | B9: 100 L tank, 48 V pump, 12 PWM nozzles with per-plant targeting | C9: 1 | D9: 3800 | E9: 3800
A10: SP-1 spot sprayer implement (replaces micro-doser) | B10: Cameras + frame + coupler | C10: 1 | D10: 1600 | E10: 1600
A11: HL-1 hauler (AB-1 base + tote rack, no arms) | B11: AB-1 base (see AB-1 sheet, less nothing) | C11: 1 | D11: 24487 | E11: 24487
A12: HL-1 hauler (AB-1 base + tote rack, no arms) | B12: 8-tote rack with 4 MDR roller zones | C12: 1 | D12: 5200 | E12: 5200
A13: SU-1 scout UAV (ArduPilot quad, multispectral) | B13: Holybro X650 frame + motors + ESCs | C13: 1 | D13: 900 | E13: 900
... A22: DK-1 dock/charger (serves ~2 UGVs) | B22: Implement-swap stand with locating cones | C22: 2 | D22: 900 | E22: 1800
